Workbook

Sheet Status
B2: New Deal Owner | C2: Strategic AM | D2: Non Strategic AM | E2: AM Accounts | F2: Non-Strategic Deals to Close | G2: Strategic Deals to Close | H2: Total Accounts | J2: Strategic Partners
B3: Daniela Reyes | C3: =countifs('All partners'!$G:$G,$B3,'All partners'!$F:$F,"Account Management",'All partners'!$H:$H,TRUE) -> 16 | D3: =countifs('All partners'!$G:$G,$B3,'All partners'!$F:$F,"Account Management",'All partners'!$H:$H,FALSE) -> 23 | E3: 1 | F3: =countifs('All partners'!$G:$G,$B3,'All partners'!$F:$F,"Business Development",'All partners'!$H:$H,FALSE) -> 28 | G3: =countifs('All partners'!$G:$G,$B3,'All partners'!$F:$F,"Business Development",'All partners'!$H:$H,TRUE) -> 10 | H3: =sum(E3:G3) -> 39 | J3: Door Openers, Ahead of the Curve, Innovators, Local Must-Have, Regulators
B4: Johanderson Guevara | C4: =countifs('All partners'!$G:$G,$B4,'All partners'!$F:$F,"Account Management",'All partners'!$H:$H,TRUE) -> 19 | D4: =countifs('All partners'!$G:$G,$B4,'All partners'!$F:$F,"Account Management",'All partners'!$H:$H,FALSE) -> 22 | E4: =sum(C4:D4) -> 41 | F4: =countifs('All partners'!$G:$G,$B4,'All partners'!$F:$F,"Business Development",'All partners'!$H:$H,FALSE) -> 13 | G4: =countifs('All partners'!$G:$G,$B4,'All partners'!$F:$F,"Business Development",'All partners'!$H:$H,TRUE) -> 10 | H4: =sum(E4:G4) -> 64 | I4: =(H4-F4) -> 51
B5: Talita Diaz Gama | C5: =countifs('All partners'!$G:$G,$B5,'All partners'!$F:$F,"Account Management",'All partners'!$H:$H,TRUE) -> 20 | D5: =countifs('All partners'!$G:$G,$B5,'All partners'!$F:$F,"Account Management",'All partners'!$H:$H,FALSE) -> 22 | E5: =sum(C5:D5) -> 42 | F5: =countifs('All partners'!$G:$G,$B5,'All partners'!$F:$F,"Business Development",'All partners'!$H:$H,FALSE) -> 22 | G5: =countifs('All partners'!$G:$G,$B5,'All partners'!$F:$F,"Business Development",'All partners'!$H:$H,TRUE) -> 16 | H5: =sum(E5:G5) -> 80 | I5: =(H5-F5) -> 58 | J5: Tier 1 : Strong Demand
B6: Mariana Castellanos | C6: =countifs('All partners'!$G:$G,$B6,'All partners'!$F:$F,"Account Management",'All partners'!$H:$H,TRUE) -> 0 | D6: =countifs('All partners'!$G:$G,$B6,'All partners'!$F:$F,"Account Management",'All partners'!$H:$H,FALSE) -> 0 | E6: =sum(C6:D6) -> 0 | F6: =countifs('All partners'!$G:$G,$B6,'All partners'!$F:$F,"Business Development",'All partners'!$H:$H,FALSE) -> 0 | G6: =countifs('All partners'!$G:$G,$B6,'All partners'!$F:$F,"Business Development",'All partners'!$H:$H,TRUE) -> 0 | H6: =sum(E6:G6) -> 0 | I6: =(H6-F6) -> 0 | J6: Strong local footprint as top payment provider locally. Popular by Merchant Demand
B7: Francisco Quintana | C7: =countifs('All partners'!$G:$G,$B7,'All partners'!$F:$F,"Account Management",'All partners'!$H:$H,TRUE) -> 4 | D7: =countifs('All partners'!$G:$G,$B7,'All partners'!$F:$F,"Account Management",'All partners'!$H:$H,FALSE) -> 14 | E7: =sum(C7:D7) -> 18 | F7: =countifs('All partners'!$G:$G,$B7,'All partners'!$F:$F,"Business Development",'All partners'!$H:$H,FALSE) -> 26 | G7: =countifs('All partners'!$G:$G,$B7,'All partners'!$F:$F,"Business Development",'All partners'!$H:$H,TRUE) -> 7 | H7: =sum(E7:G7) -> 51 | I7: =(H7-F7) -> 25
B8: Alessandra Rospigliosi | C8: =countifs('All partners'!$G:$G,$B8,'All partners'!$F:$F,"Account Management",'All partners'!$H:$H,TRUE) -> 17 | D8: =countifs('All partners'!$G:$G,$B8,'All partners'!$F:$F,"Account Management",'All partners'!$H:$H,FALSE) -> 23 | E8: =sum(C8:D8) -> 40 | F8: =countifs('All partners'!$G:$G,$B8,'All partners'!$F:$F,"Business Development",'All partners'!$H:$H,FALSE) -> 57 | G8: =countifs('All partners'!$G:$G,$B8,'All partners'!$F:$F,"Business Development",'All partners'!$H:$H,TRUE) -> 5 | H8: =sum(E8:G8) -> 102 | I8: =(H8-F8) -> 45 | J8: Tier 2 Partners (Country/Region Specific)
B9: Franklin | C9: =countifs('All partners'!$G:$G,$B9,'All partners'!$F:$F,"Account Management",'All partners'!$H:$H,TRUE) -> 0 | D9: =countifs('All partners'!$G:$G,$B9,'All partners'!$F:$F,"Account Management",'All partners'!$H:$H,FALSE) -> 0 | E9: =sum(C9:D9) -> 0 | F9: =countifs('All partners'!$G:$G,$B9,'All partners'!$F:$F,"Business Development",'All partners'!$H:$H,FALSE) -> 0 | G9: =countifs('All partners'!$G:$G,$B9,'All partners'!$F:$F,"Business Development",'All partners'!$H:$H,TRUE) -> 0 | H9: =sum(E9:G9) -> 0 | I9: =(H9-F9) -> 0 | J9: Payplug (EU), Yape (PE), Redeban (CO)
B10: Europe | C10: =countifs('All partners'!$G:$G,$B10,'All partners'!$F:$F,"Account Management",'All partners'!$H:$H,TRUE) -> 0 | D10: =countifs('All partners'!$G:$G,$B10,'All partners'!$F:$F,"Account Management",'All partners'!$H:$H,FALSE) -> 0 | E10: =sum(C10:D10) -> 0 | F10: =countifs('All partners'!$G:$G,$B10,'All partners'!$F:$F,"Business Development",'All partners'!$H:$H,FALSE) -> 0 | G10: =countifs('All partners'!$G:$G,$B10,'All partners'!$F:$F,"Business Development",'All partners'!$H:$H,TRUE) -> 0 | H10: =sum(E10:G10) -> 0 | I10: =(H10-F10) -> 0
B11: Not assigned | C11: =countifs('All partners'!$G:$G,$B11,'All partners'!$F:$F,"Account Management",'All partners'!$H:$H,TRUE) -> 1 | D11: =countifs('All partners'!$G:$G,$B11,'All partners'!$F:$F,"Account Management",'All partners'!$H:$H,FALSE) -> 8 | E11: =sum(C11:D11) -> 9 | F11: =countifs('All partners'!$G:$G,$B11,'All partners'!$F:$F,"Business Development",'All partners'!$H:$H,FALSE) -> 39 | G11: =countifs('All partners'!$G:$G,$B11,'All partners'!$F:$F,"Business Development",'All partners'!$H:$H,TRUE) -> 1 | H11: =sum(E11:G11) -> 49 | I11: =(H11-F11) -> 10
B12: Total | C12: =sum(C3:C11) -> 77 | D12: =sum(D3:D11) -> 112 | E12: =sum(C12:D12) -> 189 | F12: =sum(F3:F11) -> 185 | G12: =sum(G3:G11) -> 49 | H12: =sum(H3:H11) -> 385
J13: Tier 3 Partners
C14: =C5+G5 -> 36
J16: High Risk Partners
J17: Astropay, Bayonet, Belvo, Cielo, Circle, Conekta, D24, Epoch, Fintoc, Flutterwave, Ibex, Khipu, Kount, PayU, Kushki, LexisNexis, Mercado Pago, Monnet Payments, Niubiz, OpenPay Mexico, PagSeguro Internacional, PagSmile, PayCash, PayPhone, PayPlug, PayRetailers, PaySafe, PayValida, Pinbank, Rocketfuel, SafetyPay, Shift4, STP, Unico, Unlimit, Vesta, OKTO Payment
J19: Others: Partners outside Acquirers, PSPs, APMs

Sheet Defined Partner Tiers
A1: Partner Tier | B1: Description/ Definition | C1: Engagement Model: | D1: Contracts | E1: Examples
A2: Strategic Partners: Very important | B2: - Deep technical and commercial integration - Executive-level sponsorship on both sides - Joint roadmap planning and co-innovation - Significant revenue impact or platform dependency | C2: - Dedicated partner manager - Regular Cadence - Quarterly executive business reviews - Joint GTM, marketing, and product initiatives | D2: Must- Have Length: Yuno to remain flexible & adapt to strategic partner | E2: Checkout Stripe dLocal
A3: Tier 1: Important | B3: - High-value/ High Demand (Local Popular Payment Method) - Scalable partners that materially contribute to revenue, - Must have for Geographic Expansion | C3: - Dedicated partner manager - Regular Cadence - Quarterly executive business reviews - Joint GTM, marketing, and product initiatives - Performance-based growth plans (Joint KPIs)
A4: Tier 2: Specific to a vertical or country (light touch) | B4: - Tactical or niche value - Moderate transaction volume - Limited roadmap alignment - Opportunity-driven engagement | C4: - Dedicated Owner - Monthly Cadence - Quarterly or Bi-Annual Business Reviews - GTM only if Vertical-specific w/ Commercial Teams
A5: Tier 3: Not relevant for wider Yuno (light touch) | B5: - Partners are transactional or experimental partners that provide optional capabilities with: - low volume, - limited engagement, and - minimal operational dependency | C5: - Self-service or automated support - Dedicated Owner (low touch) - Periodic health checks only - Review potential exit criteria 2x year (house keeping)
A6: Non-managed partners (we need to find a home) | B6: Fraud, 3Ds, PayOuts, PlugIns, KYC etc

Sheet All partners
A1: Provider | B1: Country | C1: Region | D1: Deal Stage | E1: Partner offering (acquirer, APM, Fraud etc) | F1: Type of Management | G1: Partner Manager | H1: Strategic? | I1: NDA Signed and in drive | J1: KYP Status | K1: Integration Ready by Yuno | L1: Integration Used by Merchants | M1: Revshare Contract | N1: Revshare active | O1: Review to kill agreement | P1: Type of Partner | Q1: Salesforce | R1: Airtable | S1: Reports | T1: Invoice Rev Share | U1: Pricing Requests | W1: Comments | X1: Account Plan
A2: 2C2P / Ant Intl | B2: Global | C2: APAC | D2: Agreement Signed | E2: Acquirer | F2: Account Management | G2: Lily/ Daniela | H2: TRUE | I2: FALSE | J2: FALSE | K2: FALSE | L2: FALSE | M2: TRUE | N2: FALSE | O2: FALSE | P2: Strategic Partners: Very Important | Q2: FALSE | R2: TRUE | S2: FALSE | T2: FALSE
A3: 54pay/PayGate | B3: Regional | C3: Africa | D3: Agreement Signed | E3: PSP/Aggregator | F3: Account Management | G3: Alessandra Rospigliosi | H3: FALSE | I3: TRUE | J3: FALSE | K3: FALSE | L3: FALSE | M3: TRUE | N3: FALSE | O3: FALSE | P3: Tier 3 Partners | Q3: FALSE | R3: FALSE | S3: FALSE | T3: FALSE
A4: ABSA Bank | B4: Regional | C4: EMEA | D4: Opportunity Identification | E4: Acquirer | F4: Business Development | G4: Alessandra Rospigliosi | H4: FALSE | I4: FALSE | J4: FALSE | K4: FALSE | L4: FALSE | M4: FALSE | N4: FALSE | O4: FALSE | P4: Tier 2 Partners | Q4: FALSE | R4: FALSE | S4: FALSE | T4: FALSE | W4: [Space X project, Africa]
A5: Accertify | B5: Global | C5: Global | D5: Initial Negotiation | E5: Fraud Provider | F5: Business Development | G5: Daniela Reyes | H5: FALSE | I5: TRUE | J5: FALSE | K5: FALSE | L5: FALSE | M5: FALSE | N5: FALSE | O5: FALSE | P5: Tier 3 Partners | Q5: FALSE | R5: FALSE | S5: FALSE | T5: FALSE | W5: Quieren firmar agreement solo cuando tengamos caso de uso
A6: Acuotaz | B6: Peru | C6: LATAM | D6: Opportunity Identification | E6: Other | F6: Business Development | G6: Talita Diaz Gama | H6: FALSE | I6: FALSE | J6: FALSE | K6: TRUE | L6: TRUE | M6: FALSE | N6: FALSE | O6: TRUE | P6: Tier 3 Partners | Q6: TRUE | R6: TRUE | S6: FALSE | T6: FALSE | W6: BNPL - not relevant
A7: Addi | B7: Colombia | C7: LATAM | D7: Live Partner | E7: APM | F7: Account Management | G7: Talita Diaz Gama | H7: FALSE | I7: FALSE | J7: FALSE | K7: TRUE | L7: TRUE | M7: TRUE | N7: FALSE | O7: FALSE | P7: Tier 2 Partners | Q7: TRUE | R7: TRUE | S7: FALSE | T7: FALSE
A8: Adiq Pagamentos | B8: Brasil | C8: Brasil | D8: Opportunity Identification | E8: Acquirer | F8: Business Development | G8: Johanderson Guevara | H8: FALSE | I8: FALSE | J8: FALSE | K8: FALSE | L8: FALSE | M8: FALSE | N8: FALSE | O8: FALSE | P8: Tier 3 Partners | Q8: TRUE | R8: FALSE | S8: FALSE | T8: FALSE
A9: Adyen | B9: Global | C9: Global | D9: Live Partner | E9: Acquirer | F9: Business Development | G9: Daniela Reyes | H9: TRUE | I9: FALSE | J9: FALSE | K9: TRUE | L9: TRUE | M9: FALSE | N9: FALSE | O9: FALSE | P9: Tier 1 Partners (Global) | Q9: TRUE | R9: TRUE | S9: FALSE | T9: FALSE | V9: Airtable by Ale | W9: Adyen debe de pasar a la getnet de Europa
A10: Afirme | B10: Mexico | C10: North America | D10: Agreement Signed | E10: Acquirer | F10: Account Management | G10: Daniela Reyes | H10: FALSE | I10: FALSE | J10: FALSE | K10: TRUE | L10: TRUE | M10: TRUE | N10: TRUE | O10: FALSE | P10: Tier 3 Partners | Q10: TRUE | R10: TRUE | S10: FALSE | T10: FALSE | V10: Afirme works through our Prosa integration.
A11: Aiia by Mastercard | B11: Regional | C11: EMEA | D11: Opportunity Identification | E11: APM | F11: Business Development | G11: Alessandra Rospigliosi | H11: FALSE | I11: FALSE | J11: FALSE | K11: FALSE | L11: FALSE | M11: FALSE | N11: FALSE | O11: FALSE | P11: Tier 1 Partners | Q11: FALSE | R11: FALSE | S11: FALSE | T11: FALSE | W11: Open Banking
A12: Airwallex APAC | B12: Global | C12: Global | D12: Live Partner | E12: Acquirer | F12: Account Management | G12: Alessandra Rospigliosi | H12: TRUE | I12: FALSE | J12: FALSE | K12: FALSE | L12: FALSE | M12: TRUE | N12: FALSE | O12: FALSE | P12: Strategic Partners: Very Important | Q12: FALSE
A13: Airwallex USA/ LATAM | B13: USA | C13: North America | D13: Agreement Signed | E13: Acquirer | F13: Account Management | G13: Daniela Reyes | H13: TRUE | I13: FALSE | J13: FALSE | K13: FALSE | L13: FALSE | M13: FALSE | N13: FALSE | O13: FALSE | P13: Strategic Partners: Very Important | Q13: FALSE | R13: FALSE | S13: FALSE | T13: FALSE
A14: Alelo Brasil | B14: Brasil | C14: Brasil | D14: Live Partner | E14: APM | F14: Account Management | G14: Johanderson Guevara | H14: FALSE | I14: FALSE | J14: FALSE | K14: TRUE | L14: TRUE | M14: FALSE | N14: FALSE | O14: TRUE | P14: Tier 2 Partners | Q14: TRUE | R14: TRUE | S14: FALSE | T14: FALSE
A15: Alignet | B15: Peru | C15: LATAM | D15: Agreement Signed | E15: PSP/Aggregator | F15: Account Management | G15: Talita Diaz Gama | H15: FALSE | I15: FALSE | J15: FALSE | K15: FALSE | L15: FALSE | M15: TRUE | N15: FALSE | O15: FALSE | P15: Tier 3 Partners | Q15: TRUE | R15: TRUE | W15: acquirer/BNPL - They have operations in mmore LATAM countries
A16: AllinPay (International) | B16: Regional | C16: APAC | D16: Agreement Review | E16: PSP/Aggregator | F16: Business Development | G16: Lily/ Daniela | H16: FALSE | I16: FALSE | J16: FALSE | K16: FALSE | L16: FALSE | M16: FALSE | N16: FALSE | O16: FALSE | P16: Tier 2 Partners | Q16: FALSE | R16: FALSE | S16: FALSE | T16: FALSE
A17: Amazon Pay | B17: Global | C17: Global | D17: Initial Negotiation | E17: PSP/Aggregator | F17: Business Development | G17: Alessandra Rospigliosi | H17: FALSE | I17: TRUE | J17: FALSE | K17: FALSE | L17: FALSE | M17: FALSE | N17: FALSE | O17: FALSE | P17: Tier 2 Partners | Q17: FALSE | R17: FALSE | S17: FALSE | T17: FALSE | W17: They are changing their complete strategy and they want to continue conversations in two months - February (12.01)
A18: American Express | B18: Global | C18: Global | D18: Agreement Review | E18: Acquirer | F18: Business Development | G18: Daniela Reyes | H18: TRUE | I18: FALSE | J18: FALSE | K18: FALSE | L18: FALSE | M18: FALSE | N18: FALSE | O18: FALSE | P18: Strategic Partners: Very Important | Q18: FALSE | R18: FALSE | S18: FALSE | T18: FALSE | W18: They will never have a revsahre
A19: Aplazo | B19: Mexico | C19: North America | D19: Agreement Signed | E19: Acquirer | F19: Account Management | G19: Daniela Reyes | H19: FALSE | I19: FALSE | J19: FALSE | K19: FALSE | L19: FALSE | M19: TRUE | N19: FALSE | O19: FALSE | P19: Tier 3 Partners | Q19: TRUE | R19: TRUE | S19: FALSE | T19: FALSE | V19: Airtable by Ale
A20: Apple Pay | B20: Global | C20: Global | D20: Live Partner | E20: APM | F20: Account Management | G20: Daniela Reyes | H20: TRUE | I20: FALSE | J20: FALSE | K20: TRUE | L20: TRUE | M20: FALSE | N20: FALSE | O20: FALSE | P20: Tier 1 Partners | Q20: TRUE | R20: TRUE | S20: FALSE | T20: FALSE
A21: Asaas | B21: Brasil | C21: Brasil | D21: Initial Negotiation | E21: PSP/Aggregator | F21: Business Development | G21: Johanderson Guevara | H21: FALSE | I21: FALSE | J21: FALSE | K21: FALSE | L21: FALSE | M21: FALSE | N21: FALSE | O21: FALSE | P21: Tier 3 Partners | Q21: TRUE | R21: FALSE | S21: FALSE | T21: FALSE
A22: AsiaPay | B22: Regional | C22: APAC | D22: Opportunity Identification | E22: PSP/Aggregator | F22: Business Development | G22: Ale/Lily | H22: FALSE | I22: FALSE | J22: FALSE | K22: FALSE | L22: FALSE | M22: FALSE | N22: FALSE | O22: FALSE | P22: Tier 2 Partners | Q22: FALSE | R22: FALSE | S22: FALSE | T22: FALSE
A23: Astropay | B23: Global | C23: Global | D23: Live Partner | E23: APM | F23: Account Management | G23: Alessandra Rospigliosi | H23: FALSE | I23: FALSE | J23: FALSE | K23: TRUE | L23: FALSE | M23: TRUE | N23: FALSE | O23: FALSE | P23: Tier 2 Partners | Q23: TRUE | R23: TRUE | S23: FALSE | T23: TRUE
A24: Au10tix | B24: Global | C24: Global | D24: Agreement Signed | E24: Other | F24: Account Management | G24: Alessandra Rospigliosi | H24: FALSE | I24: TRUE | J24: FALSE | K24: FALSE | L24: FALSE | M24: TRUE | N24: FALSE | O24: TRUE | P24: Non-managed Partners | Q24: TRUE | R24: TRUE | S24: FALSE | T24: FALSE | W24: KYP solution, no se les ha presentado a nadie.
A25: Avenia | B25: Regional | C25: LATAM | D25: Initial Negotiation | E25: BaaS | F25: Business Development | G25: Alessandra Rospigliosi | H25: FALSE | I25: TRUE | K25: FALSE | L25: FALSE | M25: FALSE | N25: FALSE | O25: FALSE | P25: Product Partners (3Ds, Plugins)) | Q25: FALSE | R25: FALSE | S25: FALSE | T25: FALSE
A26: Azify | B26: Global | C26: Global | D26: Opportunity Identification | E26: Other | F26: Business Development | G26: Talita Diaz Gama | H26: FALSE | I26: FALSE | J26: FALSE | K26: FALSE | L26: FALSE | M26: FALSE | N26: FALSE | O26: FALSE | P26: Product Partners (3Ds, Plugins)) | Q26: FALSE | R26: FALSE | S26: FALSE | T26: FALSE | W26: BaaS
A27: Azify | B27: Brasil | C27: Brasil | D27: Opportunity Identification | E27: PSP/Aggregator | F27: Business Development | G27: Johanderson Guevara | H27: FALSE | I27: TRUE | K27: FALSE | L27: FALSE | M27: FALSE | N27: FALSE | O27: FALSE | Q27: FALSE | R27: FALSE | S27: FALSE | T27: FALSE
A28: Azul | B28: Republica Dominicana | C28: LATAM | D28: Lost | E28: Acquirer | F28: Business Development | G28: Daniela Reyes | H28: FALSE | I28: FALSE | J28: FALSE | K28: TRUE | L28: TRUE | M28: FALSE | N28: FALSE | O28: FALSE | P28: Tier 3 Partners | Q28: TRUE | R28: TRUE | S28: FALSE | T28: FALSE | V28: Airtable by Ale
A29: B2E | B29: Brasil | C29: Brasil | D29: Lost | E29: Acquirer | F29: Business Development | G29: Not assigned | H29: FALSE | I29: FALSE | J29: FALSE | K29: FALSE | L29: FALSE | M29: FALSE | N29: FALSE | O29: FALSE | Q29: FALSE | R29: FALSE | S29: FALSE | T29: FALSE
A30: Baaskit | B30: Chile | C30: LATAM | D30: Lost | E30: Acquirer | F30: Business Development | G30: Alessandra Rospigliosi | H30: FALSE | I30: FALSE | J30: FALSE | K30: FALSE | L30: FALSE | M30: FALSE | O30: FALSE | P30: Tier 3 Partners | Q30: FALSE | R30: FALSE | S30: FALSE | T30: FALSE | W30: We will reopen conversations when we have a BC
A31: BAC International Bank | B31: Regional | C31: LATAM | D31: Opportunity Identification | E31: Acquirer | F31: Business Development | G31: Daniela Reyes | H31: TRUE | I31: FALSE | J31: FALSE | K31: TRUE | L31: TRUE | M31: FALSE | N31: FALSE | O31: FALSE | P31: Tier 2 Partners | Q31: TRUE | R31: TRUE | S31: FALSE | T31: FALSE
A32: Bamboo Payments | B32: Global | C32: Global | D32: Live Partner | E32: PSP/Aggregator | F32: Account Management | G32: Talita Diaz Gama | H32: TRUE | I32: FALSE | J32: FALSE | K32: TRUE | L32: TRUE | M32: TRUE | N32: TRUE | O32: FALSE | P32: Tier 2 Partners | Q32: TRUE | R32: TRUE | S32: TRUE | T32: TRUE
A33: Banbajío | B33: Mexico | C33: North America | D33: Lost | E33: Acquirer | F33: Business Development | G33: Daniela Reyes | H33: FALSE | I33: FALSE | J33: FALSE | K33: FALSE | L33: FALSE | M33: FALSE | N33: FALSE | O33: TRUE | P33: Tier 3 Partners | Q33: TRUE | R33: TRUE | S33: FALSE | T33: FALSE
A34: Bancard | B34: Paraguai | C34: LATAM | D34: Opportunity Identification | E34: Acquirer | F34: Business Development | G34: Johanderson Guevara | H34: TRUE | I34: FALSE | K34: FALSE | L34: FALSE | M34: FALSE | N34: FALSE | O34: TRUE | P34: Tier 1 Partners | Q34: FALSE | R34: FALSE | S34: FALSE | T34: FALSE
A35: Banco BHD Leon | B35: Republica Dominicana | C35: LATAM | D35: Opportunity Identification | E35: Acquirer | F35: Business Development | G35: Daniela Reyes | H35: FALSE | I35: FALSE | J35: FALSE | K35: TRUE | L35: FALSE | M35: FALSE | N35: FALSE | O35: FALSE | P35: Tier 3 Partners | Q35: TRUE | R35: TRUE | S35: FALSE | T35: FALSE | V35: Airtable by Ale
A36: Banco Bradesco | B36: Brasil | C36: Brasil | D36: Live Partner | E36: PSP/Aggregator | F36: Business Development | G36: Johanderson Guevara | H36: TRUE | I36: FALSE | J36: FALSE | K36: TRUE | L36: TRUE | M36: FALSE | N36: FALSE | O36: FALSE | P36: Tier 2 Partners | Q36: TRUE | R36: TRUE | S36: FALSE | T36: FALSE
A37: Banco BS2 | B37: Brasil | C37: Brasil | D37: Opportunity Identification | E37: PSP/Aggregator | F37: Business Development | G37: Johanderson Guevara | H37: FALSE | I37: FALSE | J37: FALSE | K37: FALSE | L37: FALSE | M37: FALSE | N37: FALSE | O37: FALSE | P37: Tier 3 Partners | Q37: TRUE | R37: FALSE | S37: FALSE | T37: FALSE
A38: Banco BV | Banly | B38: Brasil | C38: Brasil | D38: Opportunity Identification | E38: PSP/Aggregator | F38: Business Development | G38: Johanderson Guevara | H38: FALSE | I38: TRUE | J38: FALSE | K38: FALSE | L38: FALSE | M38: FALSE | N38: FALSE | O38: FALSE | P38: Tier 3 Partners | Q38: TRUE | R38: FALSE | S38: FALSE | T38: FALSE
A39: Banco de Bogotá | B39: Colombia | C39: LATAM | D39: Opportunity Identification | E39: Acquirer | F39: Business Development | G39: Talita Diaz Gama | H39: TRUE | I39: FALSE | J39: FALSE | K39: FALSE | L39: FALSE | M39: FALSE | N39: FALSE | O39: FALSE | P39: Tier 1 Partners | Q39: TRUE | R39: TRUE | S39: FALSE | T39: FALSE
A40: Banco de Quyaquil | B40: Ecuador | C40: LATAM | D40: Opportunity Identification | E40: Acquirer | F40: Business Development | G40: Daniela Reyes | H40: FALSE | I40: FALSE | J40: FALSE | K40: FALSE | L40: FALSE | M40: FALSE | N40: FALSE | O40: FALSE | P40: Tier 2 Partners | Q40: FALSE | R40: FALSE
...

Sheet Escalations
A1: Provider | B1: Country | C1: Region | D1: Deal Stage | E1: Partner offering (acquirer, APM, Fraud etc) | F1: Type of Management | G1: Partner Manager | H1: Strategic? | I1: Type of Partner | J1: Comments | K1: Action Required | L1: Next Steps | M1: Dani Read Y/N | N1: Solved
A2: GPay | B2: Turkey | C2: MENAT | D2: Agreement Review | E2: PSP/Aggregator | F2: Business Development | G2: Francisco Quintana | H2: No | I2: Tier 2 Partners | J2: All the information provided in the KYP originates from another company; they are unwilling to disclose their relationship with that entity. There are many red flags, and the provider feels quite sketchy. As a solution, we asked Ugur and Elif to speak with the merchant to see if this volume can be redirected. Dani, I’ve tagged you on the thread with Legal that contains all the detailed information. | K2: We have yet to decide on the final move. Justo already has visibility, but we are aligning expectations and the action plan for this partner is still to be decided | M2: TRUE | N2: Solved
A3: Zain Cash | B3: Iraq | C3: MENAT | D3: Agreement Review | E3: APM | F3: Business Development | G3: Francisco Quintana | H3: No | I3: Tier 2 Partners | J3: We are all ready live with them and we dont have an agreement. Iraq could be a troubled juridiction | K3: We need to aligned with Diego and Justo how to handle this topic and that they introduce us a POC

Sheet Analysis All Hands
B13: Africa | C13: APAC | D13: Brazil | E13: EMEA | F13: Global | G13: LATAM | H13: North America
A14: Opportunity Identification | C14: 5 | D14: 7 | E14: 27 | F14: 8 | G14: 25 | H14: 6
A15: Initial Negotiation | C15: 7 | D15: 3 | E15: 9 | F15: 11 | G15: 10 | H15: 5
A16: Agreement Review | B16: 1 | C16: 19 | D16: 2 | E16: 19 | F16: 17 | G16: 6 | H16: 3
A17: Agreement Signed | B17: 4 | C17: 7 | D17: 13 | E17: 13 | F17: 43 | G17: 34 | H17: 14
A18: Live Partner | C18: 3 | D18: 32 | E18: 1 | F18: 16 | G18: 11 | H18: 3
